Workbook
Name ACABADOS: OFFSET([1]COSTOS!$Z$2,0,0,COUNTA([1]COSTOS!$Z:$Z)+2,4)
Name Asesores: OFFSET([1]Parametros!$E$2,0,0,COUNTA([1]Parametros!$E:$E)-1,1)
Name CLIENTE: OFFSET([1]Parametros!$A$2,0,0,COUNTA([1]Parametros!$A:$A)-1,1)
Name ESTADO: OFFSET([1]Parametros!$G$2,0,0,COUNTA([1]Parametros!$G:$G)-1,1)
Name invent: [2]!Inventar[Codigo Producto]
Name Tabla_Costos: OFFSET([1]COSTOS!$L$1,0,0,COUNTA([1]COSTOS!$L:$L),COUNTA([1]COSTOS!$L$1:$W$1))

Sheet BASE
A1: Código | B1: Descripción
A2: 965MPER | B2: 965 PERFIL FACHADA FLOTANTE | C2: MATE | D2: 965
A3: ADA0101 | B3: 7038 ADAPTADOR 840 MATE | C3: MATE | D3: 840
A4: ADA0102 | B4: 8025 ADAPTADOR 158 MATE | C4: MATE | D4: 158
A5: ADA0103 | B5: 744 ADAPTADOR 403 MATE | C5: MATE | D5: 403
A6: ADA0201 | B6: 8025 ADAPTADOR 158 GRIS PLATA | C6: GRIS PLATA | D6: 158
A7: ADA0204 | B7: 3831 ADAPTADOR 175 GRIS PLATA | C7: GRIS PLATA | D7: 175
A8: ADA0206 | B8: 744 ADAPTADOR 403 GRIS PLATA | C8: GRIS PLATA | D8: 403
A9: ADA0305 | B9: 3831 ADAPTADOR 175 CRUDO | C9: CRUDO | D9: 175
A10: ADA0402 | B10: 7038 ADAPTADOR 840 BLANCO | C10: BLANCO | D10: 840
A11: ADA0404 | B11: 3831 ADAPTADOR 175 BLANCO | C11: BLANCO | D11: 175
A12: ADA0405 | B12: 744 ADAPTADOR 403 BLANCO | C12: BLANCO | D12: 403
A13: ADA0501 | B13: 8025 ADAPTADOR 158 BRONCE | C13: BRONCE | D13: 158
... A18: ADA0608 | B18: 7038 ADAPTADOR 840 NEGRO | C18: NEGRO | D18: 840
A19: ALF0101 | B19: ALFAJIA S-332 MATE | C19: MATE | D19: S-332
A20: ALF0102 | B20: ALFAJIA 413 MATE | C20: MATE | D20: 413
A21: ALF0103 | B21: ALFAJIA 612 MATE | C21: MATE | D21: 612
A22: ALF0104 | B22: ALFAJIA S-012 MATE | C22: MATE | D22: S-012
A23: ALF0105 | B23: SILLAR ALFAJIA 616 MATE | C23: MATE | D23: 616
A24: ALF0110 | B24: ALFAJIA 449 MATE | C24: MATE | D24: 449
A25: ALF0111 | B25: ALFAJIA 1123 MATE | C25: MATE | D25: 1123
A26: ALF0201 | B26: ALFAJIA 612 GRIS PLATA | C26: GRIS PLATA | D26: 612
A27: ALF0202 | B27: ALFAJIA S-332 GRIS PLATA | C27: GRIS PLATA | D27: S-332
A28: ALF0203 | B28: ALFAJIA 1123 GRIS PLATA | C28: GRIS PLATA | D28: 1123
A29: ALF0204 | B29: ALFAJIA 413 GRIS PLATA | C29: GRIS PLATA | D29: 413
A30: ALF0205 | B30: ALFAJIA S-012 GRIS PLATA | C30: GRIS PLATA | D30: S-012
A31: ALF0301 | B31: ALFAJIA S-012 CRUDO | C31: CRUDO | D31: S-012
A32: ALF0302 | B32: ALFAJIA S-332 CRUDO | C32: CRUDO | D32: S-332
A33: ALF0401 | B33: ALFAJIA S-332 BLANCA | C33: BLANCO | D33: S-332
A34: ALF0402 | B34: ALFAJIA S-012 BLANCA | C34: BLANCO | D34: S-012
A35: ALF0403 | B35: ALFAJIA 413 BLANCO | C35: BLANCO | D35: 413
A36: ALF0404 | B36: ALFAJIA 1123 BLANCA | C36: BLANCO | D36: 1123
A37: ALF0501 | B37: ALFAJIA 1123 BRONCE | C37: BRONCE | D37: 1123
A38: ALF0502 | B38: ALFAJIA 413 BRONCE | C38: BRONCE | D38: 413
A39: ALF0503 | B39: ALFAJIA S-012 BRONCE | C39: BRONCE | D39: S-012
A40: ALF0505 | B40: ALFAJIA 612 BRONCE | C40: BRONCE | D40: 612
A41: ALF0532 | B41: ALFAJIA S-332 BRONCE | C41: BRONCE | D41: S-332
A42: ALF0601 | B42: ALFAJIA 1123 NEGRO | C42: NEGRO | D42: 1123
A43: ALF0602 | B43: ALFAJIA 612 NEGRA | C43: NEGRO | D43: 612
A44: ALF0603 | B44: ALFAJIA 413 NEGRA | C44: NEGRO | D44: 413
...

Sheet INV 28 FEBRERO 2026
A1: INVENTARIO FEBRERO 28 DE 2026
A2: CONS. | B2: COD TEMPLEX | C2: DESCRIPCION | D2: COLOR | E2: REF. | F2: mm | G2: Und | H2: OPD | I2: UBICACIÓN
A3: 752 | B3: U570201 | C3: =VLOOKUP(B3,BASE!$A:$B,2,0) -> U57 GRIS PLATA | D3: =VLOOKUP(B3,BASE!$A:$D,3,0) -> GRIS PLATA | E3: =VLOOKUP(B3,BASE!$A:$E,4,0) -> U-57 | F3: 2000 | G3: =+F3/6000 -> 0.33333333 | I3: P-04 | K3: 1 | L3: ALBA | M3: 7500000 | O3: 29290985
A4: 755 | B4: U570201 | C4: =VLOOKUP(B4,BASE!$A:$B,2,0) -> U57 GRIS PLATA | D4: =VLOOKUP(B4,BASE!$A:$D,3,0) -> GRIS PLATA | E4: =VLOOKUP(B4,BASE!$A:$E,4,0) -> U-57 | F4: 1880 | G4: =+F4/6000 -> 0.31333333 | I4: P-04 | K4: 2 | L4: BRYAM | M4: 3700000 | O4: 304283
A5: 910 | B5: ZOC0105 | C5: =VLOOKUP(B5,BASE!$A:$B,2,0) -> ZOCALO 9CMS S-369 BRONCE MOVIL | D5: =VLOOKUP(B5,BASE!$A:$D,3,0) -> BRONCE | E5: =VLOOKUP(B5,BASE!$A:$E,4,0) -> S-369 | F5: 1300 | G5: =+F5/6000 -> 0.21666667 | I5: R-02 | K5: 3 | L5: ALEJANDRO | M5: 2617000 | O5: 228334
A6: 1093 | B6: CAB0207 | C6: =VLOOKUP(B6,BASE!$A:$B,2,0) -> 8025 CABEZAL 151 GRIS PLATA | D6: =VLOOKUP(B6,BASE!$A:$D,3,0) -> GRIS PLATA | E6: =VLOOKUP(B6,BASE!$A:$E,4,0) -> 151 | F6: 2600 | G6: =+F6/6000 -> 0.43333333 | I6: P-01 | K6: 4 | L6: MIGUEL | M6: 2100000 | O6: 824850
A7: 1316 | B7: CAB0401 | C7: =VLOOKUP(B7,BASE!$A:$B,2,0) -> CABEZAL CABINA S-319 BLANCO | D7: =VLOOKUP(B7,BASE!$A:$D,3,0) -> BLANCO | E7: =VLOOKUP(B7,BASE!$A:$E,4,0) -> S-319 | F7: 750 | G7: =+F7/6000 -> 0.125 | I7: R-03 | K7: 5 | L7: AURA | M7: 2000000 | O7: 424637
A8: 1340 | B8: CAB0206 | C8: =VLOOKUP(B8,BASE!$A:$B,2,0) -> 8025 CABEZAL 706 BLANCO | D8: =VLOOKUP(B8,BASE!$A:$D,3,0) -> BLANCO | E8: =VLOOKUP(B8,BASE!$A:$E,4,0) -> 706 | F8: 3490 | G8: =+F8/6000 -> 0.58166667 | I8: P-08 | K8: 6 | L8: JAVIER | M8: 2000000 | O8: 3954759
A9: 1341 | B9: SIL0402 | C9: =VLOOKUP(B9,BASE!$A:$B,2,0) -> 8025 SILLAR 707 BLANCO | D9: =VLOOKUP(B9,BASE!$A:$D,3,0) -> BLANCO | E9: =VLOOKUP(B9,BASE!$A:$E,4,0) -> 707 | F9: 3490 | G9: =+F9/6000 -> 0.58166667 | I9: P-08 | K9: 7 | L9: JOSE | M9: 2000000 | O9: 406800
A10: 1546 | B10: ALF0105 | C10: =VLOOKUP(B10,BASE!$A:$B,2,0) -> SILLAR ALFAJIA 616 MATE | D10: =VLOOKUP(B10,BASE!$A:$D,3,0) -> MATE | E10: =VLOOKUP(B10,BASE!$A:$E,4,0) -> 616 | F10: 6000 | G10: =+F10/6000 -> 1 | I10: C-03 | K10: 8 | L10: CARLOS | M10: 1997000 | O10: 1000000
A11: 2054 | B11: U570201 | C11: =VLOOKUP(B11,BASE!$A:$B,2,0) -> U57 GRIS PLATA | D11: =VLOOKUP(B11,BASE!$A:$D,3,0) -> GRIS PLATA | E11: =VLOOKUP(B11,BASE!$A:$E,4,0) -> U-57 | F11: 2600 | G11: =+F11/6000 -> 0.43333333 | I11: P-04 | K11: 9 | L11: LUIS | M11: 1997000 | O11: 665500
A12: 2248 | B12: TUB0132 | C12: =VLOOKUP(B12,BASE!$A:$B,2,0) -> CUARTO CIRCULAR 1 1/2 " MATE | D12: =VLOOKUP(B12,BASE!$A:$D,3,0) -> MATE | E12: =VLOOKUP(B12,BASE!$A:$E,4,0) -> T-280 | F12: 2600 | G12: =+F12/6000 -> 0.43333333 | I12: P-03 | K12: 10 | L12: JUAN CATAÑO | M12: 1970000 | O12: 800000
A13: 2452 | B13: CAB0401 | C13: =VLOOKUP(B13,BASE!$A:$B,2,0) -> CABEZAL CABINA S-319 BLANCO | D13: =VLOOKUP(B13,BASE!$A:$D,3,0) -> BLANCO | E13: =VLOOKUP(B13,BASE!$A:$E,4,0) -> S-319 | F13: 950 | G13: =+F13/6000 -> 0.15833333 | I13: R-03 | K13: 11 | L13: NATALY | M13: 1900000 | O13: 971160
A14: 2585 | B14: CAB0203 | C14: =VLOOKUP(B14,BASE!$A:$B,2,0) -> 5020 CABEZAL 144 GRIS PLATA | D14: =VLOOKUP(B14,BASE!$A:$D,3,0) -> GRIS PLATA | E14: =VLOOKUP(B14,BASE!$A:$E,4,0) -> 144 | F14: 940 | G14: =+F14/6000 -> 0.15666667 | I14: R-03 | K14: 12 | L14: SANDRA | M14: 1900000 | O14: 259420
A15: 2719 | B15: CAB0501 | C15: =VLOOKUP(B15,BASE!$A:$B,2,0) -> CABEZAL CABINA S-319 BRONCE | D15: =VLOOKUP(B15,BASE!$A:$D,3,0) -> BRONCE | E15: =VLOOKUP(B15,BASE!$A:$E,4,0) -> S-319 | F15: 970 | G15: =+F15/6000 -> 0.16166667 | I15: R-03 | K15: 13 | L15: JUAN GOMEZ | M15: 1885000 | O15: 2732217
A16: 2979 | B16: ALF0102 | C16: =VLOOKUP(B16,BASE!$A:$B,2,0) -> ALFAJIA 413 MATE | D16: =VLOOKUP(B16,BASE!$A:$D,3,0) -> MATE | E16: =VLOOKUP(B16,BASE!$A:$E,4,0) -> 413 | F16: 2000 | G16: =+F16/6000 -> 0.33333333 | I16: P-07 | K16: 15 | L16: ALBERTO | M16: 1750905
A17: 2981 | B17: ALF0102 | C17: =VLOOKUP(B17,BASE!$A:$B,2,0) -> ALFAJIA 413 MATE | D17: =VLOOKUP(B17,BASE!$A:$D,3,0) -> MATE | E17: =VLOOKUP(B17,BASE!$A:$E,4,0) -> 413 | F17: 1800 | G17: =+F17/6000 -> 0.3 | I17: P-07 | K17: 16 | L17: ELIECER | M17: 1750905
A18: 2992 | B18: ALF0102 | C18: =VLOOKUP(B18,BASE!$A:$B,2,0) -> ALFAJIA 413 MATE | D18: =VLOOKUP(B18,BASE!$A:$D,3,0) -> MATE | E18: =VLOOKUP(B18,BASE!$A:$E,4,0) -> 413 | F18: 2100 | G18: =+F18/6000 -> 0.35 | I18: P-07 | K18: 17 | L18: JORGE | M18: 1750905 | O18: =SUM(O3:O17) -> 41862945
A19: 3203 | B19: ALF0604 | C19: =VLOOKUP(B19,BASE!$A:$B,2,0) -> ALFAJIA S-332 NEGRA | D19: =VLOOKUP(B19,BASE!$A:$D,3,0) -> NEGRO | E19: =VLOOKUP(B19,BASE!$A:$E,4,0) -> S-332 | F19: 900 | G19: =+F19/6000 -> 0.15 | I19: R-01
A20: 3255 | B20: ZOC0105 | C20: =VLOOKUP(B20,BASE!$A:$B,2,0) -> ZOCALO 9CMS S-369 BRONCE MOVIL | D20: =VLOOKUP(B20,BASE!$A:$D,3,0) -> BRONCE | E20: =VLOOKUP(B20,BASE!$A:$E,4,0) -> S-369 | F20: 1700 | G20: =+F20/6000 -> 0.28333333 | I20: P-03
A21: 3291 | B21: U890602 | C21: =VLOOKUP(B21,BASE!$A:$B,2,0) -> U89 NEGRO | D21: =VLOOKUP(B21,BASE!$A:$D,3,0) -> NEGRO | E21: =VLOOKUP(B21,BASE!$A:$E,4,0) -> U-89 | F21: 6000 | G21: =+F21/6000 -> 1 | I21: C-01
A22: 3295 | B22: SIL0610 | C22: =VLOOKUP(B22,BASE!$A:$B,2,0) -> 8025 SILLAR 707 NEGRO | D22: =VLOOKUP(B22,BASE!$A:$D,3,0) -> NEGRO | E22: =VLOOKUP(B22,BASE!$A:$E,4,0) -> 707 | F22: 2800 | G22: =+F22/6000 -> 0.46666667 | I22: P-08
A23: 3317 | B23: TUB0114 | C23: =VLOOKUP(B23,BASE!$A:$B,2,0) -> TUBULAR T-280 MATE | D23: =VLOOKUP(B23,BASE!$A:$D,3,0) -> MATE | E23: =VLOOKUP(B23,BASE!$A:$E,4,0) -> T-280 | F23: 2400 | G23: =+F23/6000 -> 0.4 | I23: P-03
A24: 3737 | B24: TPR0402 | C24: =VLOOKUP(B24,BASE!$A:$B,2,0) -> 5020 TRASLAPE REFORZADO 462 BLANCO | D24: =VLOOKUP(B24,BASE!$A:$D,3,0) -> BLANCO | E24: =VLOOKUP(B24,BASE!$A:$E,4,0) -> 462 | F24: 3300 | G24: =+F24/6000 -> 0.55 | I24: P-05
A25: 3817 | B25: U890101 | C25: =VLOOKUP(B25,BASE!$A:$B,2,0) -> U-089 MATE | D25: =VLOOKUP(B25,BASE!$A:$D,3,0) -> MATE | E25: =VLOOKUP(B25,BASE!$A:$E,4,0) -> U-89 | F25: 1700 | G25: =+F25/6000 -> 0.28333333 | I25: P-04
A26: 3970 | B26: CAB0401 | C26: =VLOOKUP(B26,BASE!$A:$B,2,0) -> CABEZAL CABINA S-319 BLANCO | D26: =VLOOKUP(B26,BASE!$A:$D,3,0) -> BLANCO | E26: =VLOOKUP(B26,BASE!$A:$E,4,0) -> S-319 | F26: 900 | G26: =+F26/6000 -> 0.15 | I26: R-03
A27: 4055 | B27: TUB0111 | C27: =VLOOKUP(B27,BASE!$A:$B,2,0) -> TUBULAR T-101 MATE | D27: =VLOOKUP(B27,BASE!$A:$D,3,0) -> MATE | E27: =VLOOKUP(B27,BASE!$A:$E,4,0) -> T-101 | F27: 1800 | G27: =+F27/6000 -> 0.3 | I27: P-04
A28: 4072 | B28: SIL0501 | C28: =VLOOKUP(B28,BASE!$A:$B,2,0) -> SILLAR CABINA S-201 BRONCE | D28: =VLOOKUP(B28,BASE!$A:$D,3,0) -> BRONCE | E28: =VLOOKUP(B28,BASE!$A:$E,4,0) -> S-201 | F28: 900 | G28: =+F28/6000 -> 0.15 | I28: R-03
A29: 4264 | B29: DIV0205 | C29: =VLOOKUP(B29,BASE!$A:$B,2,0) -> 3831 DIVISOR 1103 MATE | D29: =VLOOKUP(B29,BASE!$A:$D,3,0) -> MATE | E29: =VLOOKUP(B29,BASE!$A:$E,4,0) -> 1103 | F29: 1800 | G29: =+F29/6000 -> 0.3 | I29: P-04
A30: 4279 | B30: JAM0403 | C30: =VLOOKUP(B30,BASE!$A:$B,2,0) -> 5020 JAMBA 193 BLANCO | D30: =VLOOKUP(B30,BASE!$A:$D,3,0) -> BLANCO | E30: =VLOOKUP(B30,BASE!$A:$E,4,0) -> 193 | F30: 600 | G30: =+F30/6000 -> 0.1 | I30: R-04
... A52: 5743 | B52: ALF0503 | C52: =VLOOKUP(B52,BASE!$A:$B,2,0) -> ALFAJIA S-012 BRONCE | D52: =VLOOKUP(B52,BASE!$A:$D,3,0) -> BRONCE | E52: =VLOOKUP(B52,BASE!$A:$E,4,0) -> S-012 | F52: 1100 | G52: =+F52/6000 -> 0.18333333 | I52: R-01
A53: 5745 | B53: SIN CODIGO | C53: =VLOOKUP(B53,BASE!$A:$B,2,0) -> #N/A | D53: =VLOOKUP(B53,BASE!$A:$D,3,0) -> #N/A | E53: 1103 | F53: 3900 | G53: =+F53/6000 -> 0.65 | I53: P-06
A54: 5854 | B54: TUB0201 | C54: =VLOOKUP(B54,BASE!$A:$B,2,0) -> TUBULAR T-244 GRIS PLATA | D54: =VLOOKUP(B54,BASE!$A:$D,3,0) -> GRIS PLATA | E54: =VLOOKUP(B54,BASE!$A:$E,4,0) -> T-244 | F54: 2500 | G54: =+F54/6000 -> 0.41666667 | I54: P-04
A55: 5941 | B55: SILL0501 | C55: =VLOOKUP(B55,BASE!$A:$B,2,0) -> 5020 SILLAR ALFAJIA 581 BRONCE | D55: =VLOOKUP(B55,BASE!$A:$D,3,0) -> BRONCE | E55: =VLOOKUP(B55,BASE!$A:$E,4,0) -> 581 | F55: 1100 | G55: =+F55/6000 -> 0.18333333 | I55: R-02
A56: 6004 | B56: TRA0102 | C56: =VLOOKUP(B56,BASE!$A:$B,2,0) -> 5020 TRASLAPE 192 BRONCE | D56: =VLOOKUP(B56,BASE!$A:$D,3,0) -> BRONCE | E56: =VLOOKUP(B56,BASE!$A:$E,4,0) -> 192 | F56: 6000 | G56: =+F56/6000 -> 1 | I56: C-02
A57: 6115 | B57: SIL0207 | C57: =VLOOKUP(B57,BASE!$A:$B,2,0) -> 8025 SILLAR 150 GRIS PLATA | D57: =VLOOKUP(B57,BASE!$A:$D,3,0) -> GRIS PLATA | E57: =VLOOKUP(B57,BASE!$A:$E,4,0) -> 150 | F57: 1200 | G57: =+F57/6000 -> 0.2 | I57: R-02
A58: 6116 | B58: CAB0207 | C58: =VLOOKUP(B58,BASE!$A:$B,2,0) -> 8025 CABEZAL 151 GRIS PLATA | D58: =VLOOKUP(B58,BASE!$A:$D,3,0) -> GRIS PLATA | E58: =VLOOKUP(B58,BASE!$A:$E,4,0) -> 151 | F58: 1200 | G58: =+F58/6000 -> 0.2 | I58: R-02
A59: 6117 | B59: CAB0207 | C59: =VLOOKUP(B59,BASE!$A:$B,2,0) -> 8025 CABEZAL 151 GRIS PLATA | D59: =VLOOKUP(B59,BASE!$A:$D,3,0) -> GRIS PLATA | E59: =VLOOKUP(B59,BASE!$A:$E,4,0) -> 151 | F59: 1200 | G59: =+F59/6000 -> 0.2 | I59: R-02
A60: 6118 | B60: ENG0201 | C60: =VLOOKUP(B60,BASE!$A:$B,2,0) -> 8025 ENGANCHE 191 GRIS PLATA | D60: =VLOOKUP(B60,BASE!$A:$D,3,0) -> GRIS PLATA | E60: =VLOOKUP(B60,BASE!$A:$E,4,0) -> 191 | F60: 1300 | G60: =+F60/6000 -> 0.21666667 | I60: R-02
A61: 6119 | B61: ENG0201 | C61: =VLOOKUP(B61,BASE!$A:$B,2,0) -> 8025 ENGANCHE 191 GRIS PLATA | D61: =VLOOKUP(B61,BASE!$A:$D,3,0) -> GRIS PLATA | E61: =VLOOKUP(B61,BASE!$A:$E,4,0) -> 191 | F61: 1300 | G61: =+F61/6000 -> 0.21666667 | I61: R-02
...

Sheet PERFILERIA EN PROCESO
A1: ODP | B1: COD TEMPLEX | C1: DESCRIPCION | D1: COLOR | E1: REF. | F1: MM | G1: conversión
A2: 23625 | B2: PPR0101 | C2: =VLOOKUP(B2,BASE!$A:$B,2,0) -> 3831 PISAVIDRIO 177 MATE | D2: =VLOOKUP(B2,BASE!$A:$D,3,0) -> MATE | E2: =VLOOKUP(B2,BASE!$A:$E,4,0) -> 177 | F2: 2100 | G2: =+F2/6000 -> 0.35 | H2: 7486 | J2: facturadas sin salida
A3: 23637 | B3: SIL0609 | C3: =VLOOKUP(B3,BASE!$A:$B,2,0) -> 8025 SILLAR 150 NEGRO | D3: =VLOOKUP(B3,BASE!$A:$D,3,0) -> NEGRO | E3: =VLOOKUP(B3,BASE!$A:$E,4,0) -> 150 | F3: 1800 | G3: =+F3/6000 -> 0.3 | J3: 23639 | K3: FUNDACION GREATER MEDELLIN
A4: 23637 | B4: CAB0604 | C4: =VLOOKUP(B4,BASE!$A:$B,2,0) -> 8025 CABEZAL 151 NEGRO | D4: =VLOOKUP(B4,BASE!$A:$D,3,0) -> NEGRO | E4: =VLOOKUP(B4,BASE!$A:$E,4,0) -> 151 | F4: 1800 | G4: =+F4/6000 -> 0.3 | H4: 7504 | J4: 23677 | K4: CREATUM ACCESORIOS SAS
A5: 23637 | B5: JAM0609 | C5: =VLOOKUP(B5,BASE!$A:$B,2,0) -> 8025 JAMBA 152 NEGRO | D5: =VLOOKUP(B5,BASE!$A:$D,3,0) -> NEGRO | E5: =VLOOKUP(B5,BASE!$A:$E,4,0) -> 152 | F5: 4100 | G5: =+F5/6000 -> 0.68333333 | J5: 23702 | K5: APOTEMA S.A.S.
A6: 23637 | B6: ENG0607 | C6: =VLOOKUP(B6,BASE!$A:$B,2,0) -> 8025 ENGANCHE 191 NEGRO | D6: =VLOOKUP(B6,BASE!$A:$D,3,0) -> NEGRO | E6: =VLOOKUP(B6,BASE!$A:$E,4,0) -> 191 | F6: 4000 | G6: =+F6/6000 -> 0.66666667
A7: 23637 | B7: HORS061 | C7: =VLOOKUP(B7,BASE!$A:$B,2,0) -> 8025 HORIZONTAL SUPERIOR 156 NEGRO | D7: =VLOOKUP(B7,BASE!$A:$D,3,0) -> NEGRO | E7: =VLOOKUP(B7,BASE!$A:$E,4,0) -> 156 | F7: 1600 | G7: =+F7/6000 -> 0.26666667
A8: 23637 | B8: HOI0602 | C8: =VLOOKUP(B8,BASE!$A:$B,2,0) -> 8025 HORIZONTAL INFERIOR 157 NEGRO | D8: =VLOOKUP(B8,BASE!$A:$D,3,0) -> NEGRO | E8: =VLOOKUP(B8,BASE!$A:$E,4,0) -> 157 | F8: 1600 | G8: =+F8/6000 -> 0.26666667
A9: 23637 | B9: TRA0608 | C9: =VLOOKUP(B9,BASE!$A:$B,2,0) -> 8025 TRASLAPE 190 NEGRO | D9: =VLOOKUP(B9,BASE!$A:$D,3,0) -> NEGRO | E9: =VLOOKUP(B9,BASE!$A:$E,4,0) -> 190 | F9: 4000 | G9: =+F9/6000 -> 0.66666667
A10: 23662 | B10: PER0301 | C10: =VLOOKUP(B10,BASE!$A:$B,2,0) -> PERFIL F 463 MATE | D10: =VLOOKUP(B10,BASE!$A:$D,3,0) -> MATE | E10: =VLOOKUP(B10,BASE!$A:$E,4,0) -> F-463 | F10: 2000 | G10: =+F10/6000 -> 0.33333333 | H10: 7517
A11: 23662 | B11: U320101 | C11: =VLOOKUP(B11,BASE!$A:$B,2,0) -> U32 MATE | D11: =VLOOKUP(B11,BASE!$A:$D,3,0) -> MATE | E11: =VLOOKUP(B11,BASE!$A:$E,4,0) -> U-32 | F11: 1800 | G11: =+F11/6000 -> 0.3
A12: 23669 | B12: U320101 | C12: =VLOOKUP(B12,BASE!$A:$B,2,0) -> U32 MATE | D12: =VLOOKUP(B12,BASE!$A:$D,3,0) -> MATE | E12: =VLOOKUP(B12,BASE!$A:$E,4,0) -> U-32 | F12: 4000 | G12: =+F12/6000 -> 0.66666667 | H12: 7520
A13: 23669 | B13: TUB0302 | C13: =VLOOKUP(B13,BASE!$A:$B,2,0) -> TUBULAR T-76 CRUDO | D13: =VLOOKUP(B13,BASE!$A:$D,3,0) -> CRUDO | E13: =VLOOKUP(B13,BASE!$A:$E,4,0) -> T-76 | F13: 3400 | G13: =+F13/6000 -> 0.56666667
A14: 23670 | B14: PER0301 | C14: =VLOOKUP(B14,BASE!$A:$B,2,0) -> PERFIL F 463 MATE | D14: =VLOOKUP(B14,BASE!$A:$D,3,0) -> MATE | E14: =VLOOKUP(B14,BASE!$A:$E,4,0) -> F-463 | F14: 900 | G14: =+F14/6000 -> 0.15 | H14: 7525
A15: 23670 | B15: U320101 | C15: =VLOOKUP(B15,BASE!$A:$B,2,0) -> U32 MATE | D15: =VLOOKUP(B15,BASE!$A:$D,3,0) -> MATE | E15: =VLOOKUP(B15,BASE!$A:$E,4,0) -> U-32 | F15: 700 | G15: =+F15/6000 -> 0.11666667
A16: INVENTARIO | B16: TUB0302 | C16: =VLOOKUP(B16,BASE!$A:$B,2,0) -> TUBULAR T-76 CRUDO | D16: =VLOOKUP(B16,BASE!$A:$D,3,0) -> CRUDO | E16: =VLOOKUP(B16,BASE!$A:$E,4,0) -> T-76 | F16: 30000 | G16: =+F16/6000 -> 5
A17: INVENTARIO | B17: U680101 | C17: =VLOOKUP(B17,BASE!$A:$B,2,0) -> U68 MATE | D17: =VLOOKUP(B17,BASE!$A:$D,3,0) -> MATE | E17: =VLOOKUP(B17,BASE!$A:$E,4,0) -> U-68 | F17: 48000 | G17: =+F17/6000 -> 8
A18: 23634 | B18: SIL0609 | C18: =VLOOKUP(B18,BASE!$A:$B,2,0) -> 8025 SILLAR 150 NEGRO | D18: =VLOOKUP(B18,BASE!$A:$D,3,0) -> NEGRO | E18: =VLOOKUP(B18,BASE!$A:$E,4,0) -> 150 | F18: 66000 | G18: =+F18/6000 -> 11 | H18: 11 | I18: =H18*6000 -> 66000
A19: 23634 | B19: CAB0604 | C19: =VLOOKUP(B19,BASE!$A:$B,2,0) -> 8025 CABEZAL 151 NEGRO | D19: =VLOOKUP(B19,BASE!$A:$D,3,0) -> NEGRO | E19: =VLOOKUP(B19,BASE!$A:$E,4,0) -> 151 | F19: 66000 | G19: =+F19/6000 -> 11 | H19: 11 | I19: =H19*6000 -> 66000
A20: 23634 | B20: JAM0609 | C20: =VLOOKUP(B20,BASE!$A:$B,2,0) -> 8025 JAMBA 152 NEGRO | D20: =VLOOKUP(B20,BASE!$A:$D,3,0) -> NEGRO | E20: =VLOOKUP(B20,BASE!$A:$E,4,0) -> 152 | F20: 72000 | G20: =+F20/6000 -> 12 | H20: 11 | I20: =(H20*6000)+6000 -> 72000
A21: 23634 | B21: TRA0608 | C21: =VLOOKUP(B21,BASE!$A:$B,2,0) -> 8025 TRASLAPE 190 NEGRO | D21: =VLOOKUP(B21,BASE!$A:$D,3,0) -> NEGRO | E21: =VLOOKUP(B21,BASE!$A:$E,4,0) -> 190 | F21: 108000 | G21: =+F21/6000 -> 18 | H21: 18 | I21: =H21*6000 -> 108000
A22: 23634 | B22: ENG0607 | C22: =VLOOKUP(B22,BASE!$A:$B,2,0) -> 8025 ENGANCHE 191 NEGRO | D22: =VLOOKUP(B22,BASE!$A:$D,3,0) -> NEGRO | E22: =VLOOKUP(B22,BASE!$A:$E,4,0) -> 191 | F22: 108000 | G22: =+F22/6000 -> 18 | H22: 17 | I22: =(H22*6000)+6000 -> 108000
A23: 23634 | B23: HORS061 | C23: =VLOOKUP(B23,BASE!$A:$B,2,0) -> 8025 HORIZONTAL SUPERIOR 156 NEGRO | D23: =VLOOKUP(B23,BASE!$A:$D,3,0) -> NEGRO | E23: =VLOOKUP(B23,BASE!$A:$E,4,0) -> 156 | F23: 60000 | G23: =+F23/6000 -> 10 | H23: 10 | I23: =H23*6000 -> 60000
A24: 23634 | B24: HOI0602 | C24: =VLOOKUP(B24,BASE!$A:$B,2,0) -> 8025 HORIZONTAL INFERIOR 157 NEGRO | D24: =VLOOKUP(B24,BASE!$A:$D,3,0) -> NEGRO | E24: =VLOOKUP(B24,BASE!$A:$E,4,0) -> 157 | F24: 60000 | G24: =+F24/6000 -> 10 | H24: 10 | I24: =H24*6000 -> 60000
A25: 23634 | B25: ADA0603 | C25: =VLOOKUP(B25,BASE!$A:$B,2,0) -> 8025 ADAPTADOR 158 NEGRO | D25: =VLOOKUP(B25,BASE!$A:$D,3,0) -> NEGRO | E25: =VLOOKUP(B25,BASE!$A:$E,4,0) -> 158 | F25: 18000 | G25: =+F25/6000 -> 3 | H25: 3 | I25: =H25*6000 -> 18000
A26: 23634 | B26: SIL0606 | C26: =VLOOKUP(B26,BASE!$A:$B,2,0) -> 3831 SILLAR CABEZAL 173 NEGRO | D26: =VLOOKUP(B26,BASE!$A:$D,3,0) -> NEGRO | E26: =VLOOKUP(B26,BASE!$A:$E,4,0) -> 173 | F26: 216000 | G26: =+F26/6000 -> 36 | H26: 36 | I26: =H26*6000 -> 216000
A27: 23634 | B27: JAM0604 | C27: =VLOOKUP(B27,BASE!$A:$B,2,0) -> 3831 JAMBA 174 NEGRO | D27: =VLOOKUP(B27,BASE!$A:$D,3,0) -> NEGRO | E27: =VLOOKUP(B27,BASE!$A:$E,4,0) -> 174 | F27: 36000 | G27: =+F27/6000 -> 6 | H27: 6 | I27: =H27*6000 -> 36000
A28: 23634 | B28: PIS0602 | C28: =VLOOKUP(B28,BASE!$A:$B,2,0) -> 3831 PISAVIDRIO 177 NEGRO | D28: =VLOOKUP(B28,BASE!$A:$D,3,0) -> NEGRO | E28: =VLOOKUP(B28,BASE!$A:$E,4,0) -> 177 | F28: 180000 | G28: =+F28/6000 -> 30 | H28: 30 | I28: =H28*6000 -> 180000
A29: 23634 | B29: DIV0604 | C29: =VLOOKUP(B29,BASE!$A:$B,2,0) -> 3831 DIVISOR 292 NEGRO | D29: =VLOOKUP(B29,BASE!$A:$D,3,0) -> NEGRO | E29: =VLOOKUP(B29,BASE!$A:$E,4,0) -> 292 | F29: 18000 | G29: =+F29/6000 -> 3 | H29: 3 | I29: =H29*6000 -> 18000
A30: 23634 | B30: PER0601 | C30: =VLOOKUP(B30,BASE!$A:$B,2,0) -> PERSIANA 315 NEGRO | D30: =VLOOKUP(B30,BASE!$A:$D,3,0) -> NEGRO | E30: =VLOOKUP(B30,BASE!$A:$E,4,0) -> 315 | F30: 138000 | G30: =+F30/6000 -> 23 | H30: 23 | I30: =H30*6000 -> 138000
A31: 23634 | B31: TUB0602 | C31: =VLOOKUP(B31,BASE!$A:$B,2,0) -> TUBULAR T-94 NEGRO | D31: =VLOOKUP(B31,BASE!$A:$D,3,0) -> NEGRO | E31: =VLOOKUP(B31,BASE!$A:$E,4,0) -> T-94 | F31: 108000 | G31: =+F31/6000 -> 18 | H31: 18 | I31: =H31*6000 -> 108000
A32: 23634 | B32: ALF0603 | C32: =VLOOKUP(B32,BASE!$A:$B,2,0) -> ALFAJIA 413 NEGRA | D32: =VLOOKUP(B32,BASE!$A:$D,3,0) -> NEGRO | E32: =VLOOKUP(B32,BASE!$A:$E,4,0) -> 413 | F32: 72000 | G32: =+F32/6000 -> 12 | H32: 12 | I32: =H32*6000 -> 72000
A33: 23671 | B33: SIL0744 | C33: =VLOOKUP(B33,BASE!$A:$B,2,0) -> 744 SILLAR 387 MATE | D33: =VLOOKUP(B33,BASE!$A:$D,3,0) -> MATE | E33: =VLOOKUP(B33,BASE!$A:$E,4,0) -> 387 | F33: 13300 | G33: =+F33/6000 -> 2.2166667
A34: 23671 | B34: CAB0104 | C34: =VLOOKUP(B34,BASE!$A:$B,2,0) -> 744 CABEZAL 392 MATE | D34: =VLOOKUP(B34,BASE!$A:$D,3,0) -> MATE | E34: =VLOOKUP(B34,BASE!$A:$E,4,0) -> 392 | F34: 13300 | G34: =+F34/6000 -> 2.2166667
A35: 23671 | B35: ENG0101 | C35: =VLOOKUP(B35,BASE!$A:$B,2,0) -> 744 ENGANCHE 391 MATE | D35: =VLOOKUP(B35,BASE!$A:$D,3,0) -> MATE | E35: =VLOOKUP(B35,BASE!$A:$E,4,0) -> 391 | F35: 24000 | G35: =+F35/6000 -> 4
A36: 23671 | B36: TRA0105 | C36: =VLOOKUP(B36,BASE!$A:$B,2,0) -> 744 TRASLAPE 388 MATE | D36: =VLOOKUP(B36,BASE!$A:$D,3,0) -> MATE | E36: =VLOOKUP(B36,BASE!$A:$E,4,0) -> 388 | F36: 19500 | G36: =+F36/6000 -> 3.25
A37: 23671 | B37: HOI0101 | C37: =VLOOKUP(B37,BASE!$A:$B,2,0) -> 744 HORIZONTAL INFERIOR 390 MATE | D37: =VLOOKUP(B37,BASE!$A:$D,3,0) -> MATE | E37: =VLOOKUP(B37,BASE!$A:$E,4,0) -> 390 | F37: 13300 | G37: =+F37/6000 -> 2.2166667
A38: 23671 | B38: HOS0101 | C38: =VLOOKUP(B38,BASE!$A:$B,2,0) -> 744 HORIZONTAL SUPERIOR 389 MATE | D38: =VLOOKUP(B38,BASE!$A:$D,3,0) -> MATE | E38: =VLOOKUP(B38,BASE!$A:$E,4,0) -> 389 | F38: 13300 | G38: =+F38/6000 -> 2.2166667
A39: 23671 | B39: JAM0108 | C39: =VLOOKUP(B39,BASE!$A:$B,2,0) -> 744 JAMBA 393 MATE | D39: =VLOOKUP(B39,BASE!$A:$D,3,0) -> MATE | E39: =VLOOKUP(B39,BASE!$A:$E,4,0) -> 393 | F39: 12000 | G39: =+F39/6000 -> 2
A40: 23671 | B40: ALF0111 | C40: =VLOOKUP(B40,BASE!$A:$B,2,0) -> ALFAJIA 1123 MATE | D40: =VLOOKUP(B40,BASE!$A:$D,3,0) -> MATE | E40: =VLOOKUP(B40,BASE!$A:$E,4,0) -> 1123 | F40: 18000 | G40: =+F40/6000 -> 3
...

Sheet ACCESORIOS
A1: Código | B1: Descripción
A2: ACCBA02 | B2: ACC. BARRA ESTABILIZADORA EN U NEGRO
A3: ACCBP01 | B3: ACC. BARRA ESTABILIZADORA PISTOLA
A4: ARA0103 | B4: ARANDELA DE BRONCE
A5: BAO0301 | B5: BISAGRA OMEGA 3"
A6: BAO0602 | B6: BISAGRA OMEGA 4" NEGRA
A7: BDO0306 | B7: BISAGRA DOBLE 180° NEGRA
A8: BDRTPLK | B8: BISAGRA VENTANA NOVUS
A9: BHA1101 | B9: BOTON HALADERA ACERO TAMBOR
A10: BHS0101 | B10: BISAGRA HIDRAULICA SPEEDY M60 TRAFICO PESADO
A11: BIB0101 | B11: BISAGRA BANDERA
A12: BIN0301 | B12: BISAGRA INVERTIDA CROMO 1 PUNTO
... A93: ZCE0104 | B93: ZOCALO CON BASE Y CERRADURA

Sheet ACCESORIOS EN PROCESO
A1: ODP | B1: COD TEMPLEX | C1: DESCRIPCION | D1: CANTIDAD | E1: MEDIDA
A2: 23637 | B2: ROD8025NY | C2: =VLOOKUP(B2,ACCESORIOS!$A:$B,2,0) -> RODAMIENTO 8025 NYLON | D2: 2 | E2: UND
A3: 23637 | B3: EMPA8025 | C3: =VLOOKUP(B3,ACCESORIOS!$A:$B,2,0) -> EMPAQUE 8025 REF 30110 | D3: 11 | E3: MTS
A4: 23637 | B4: GSU8025 | C4: =VLOOKUP(B4,ACCESORIOS!$A:$B,2,0) -> GUIA SUPERIOR 8025 | D4: 2 | E4: MTS
A5: 23637 | B5: GIN8025 | C5: =VLOOKUP(B5,ACCESORIOS!$A:$B,2,0) -> GUIA INFERIOR 8025 | D5: 2 | E5: UND
A6: 23637 | B6: FEL0101 | C6: =VLOOKUP(B6,ACCESORIOS!$A:$B,2,0) -> FELPA | D6: 4 | E6: MTS
A7: 23637 | B7: CYM0101 | C7: =VLOOKUP(B7,ACCESORIOS!$A:$B,2,0) -> CHAPA YALE PICOLORO MEDIO CILINDRO | D7: 1 | E7: UND
A8: 23637 | B8: M802506 | C8: =VLOOKUP(B8,ACCESORIOS!$A:$B,2,0) -> MANIJA 8025 NEGRO | D8: 2 | E8: UND
A9: 23669 | B9: BSE1201 | C9: =VLOOKUP(B9,ACCESORIOS!$A:$B,2,0) -> BISAGRA SENCILLA 28-40 ACERO | D9: 4 | E9: UND
A10: 23669 | B10: BHA1101 | C10: =VLOOKUP(B10,ACCESORIOS!$A:$B,2,0) -> BOTON HALADERA ACERO TAMBOR | D10: 2 | E10: UND
A11: 23669 | B11: PER0902 | C11: =VLOOKUP(B11,ACCESORIOS!$A:$B,2,0) -> PERFIL ACRILICO 1.20 MTS | D11: 2 | E11: UND
A12: 23634 | B12: ROD8025NY | C12: =VLOOKUP(B12,ACCESORIOS!$A:$B,2,0) -> RODAMIENTO 8025 NYLON | D12: 96 | E12: UND
A13: 23634 | B13: EMPA8025 | C13: =VLOOKUP(B13,ACCESORIOS!$A:$B,2,0) -> EMPAQUE 8025 REF 30110 | D13: 400 | E13: MTS
... A30: 23683 | B30: ROD0401 | C30: =VLOOKUP(B30,ACCESORIOS!$A:$B,2,0) -> RODACHINA DE CABINA | D30: 4 | E30: UND
C31: =VLOOKUP(B31,ACCESORIOS!$A:$B,2,0) -> #N/A
C32: =VLOOKUP(B32,ACCESORIOS!$A:$B,2,0) -> #N/A
C33: =VLOOKUP(B33,ACCESORIOS!$A:$B,2,0) -> #N/A
C34: =VLOOKUP(B34,ACCESORIOS!$A:$B,2,0) -> #N/A
C35: =VLOOKUP(B35,ACCESORIOS!$A:$B,2,0) -> #N/A
C36: =VLOOKUP(B36,ACCESORIOS!$A:$B,2,0) -> #N/A
C37: =VLOOKUP(B37,ACCESORIOS!$A:$B,2,0) -> #N/A
C38: =VLOOKUP(B38,ACCESORIOS!$A:$B,2,0) -> #N/A
C39: =VLOOKUP(B39,ACCESORIOS!$A:$B,2,0) -> #N/A
C40: =VLOOKUP(B40,ACCESORIOS!$A:$B,2,0) -> #N/A
C41: =VLOOKUP(B41,ACCESORIOS!$A:$B,2,0) -> #N/A
C42: =VLOOKUP(B42,ACCESORIOS!$A:$B,2,0) -> #N/A
... C44: =VLOOKUP(B44,ACCESORIOS!$A:$B,2,0) -> #N/A

Sheet UNIFICADO x CODIGO
A1: Etiquetas de fila | B1: Suma de conversión
A2: ADA0102 | B2: 0.26666667
A3: ADA0103 | B3: 1
A4: ADA0201 | B4: 0.81666667
A5: ADA0206 | B5: 0.65
A6: ADA0404 | B6: 0.16666667
A7: ADA0405 | B7: 0.66666667
A8: ada0504 | B8: 0.75
A9: ADA0601 | B9: 0.16666667
A10: ADA0603 | B10: 4.3
A11: ADA0606 | B11: 1.5
A12: ADA0608 | B12: 0.43333333
A13: ALF0101 | B13: 0.51666667
... A300: ZSE0101 | B300: 0.16666667
A301: (en blanco)
A302: Total general | B302: 408.76817

Sheet TD mes
A1: codigo | B1: descripcion | C1: Fisica
A2: ='UNIFICADO x CODIGO'!A2 -> ADA0102 | B2: =VLOOKUP(A2,BASE!A:B,2,0) -> 8025 ADAPTADOR 158 MATE | C2: ='UNIFICADO x CODIGO'!B2 -> 0.26666667
A3: ='UNIFICADO x CODIGO'!A3 -> ADA0103 | B3: =VLOOKUP(A3,BASE!A:B,2,0) -> 744 ADAPTADOR 403 MATE | C3: ='UNIFICADO x CODIGO'!B3 -> 1
A4: ='UNIFICADO x CODIGO'!A4 -> ADA0201 | B4: =VLOOKUP(A4,BASE!A:B,2,0) -> 8025 ADAPTADOR 158 GRIS PLATA | C4: ='UNIFICADO x CODIGO'!B4 -> 0.81666667
A5: ='UNIFICADO x CODIGO'!A5 -> ADA0206 | B5: =VLOOKUP(A5,BASE!A:B,2,0) -> 744 ADAPTADOR 403 GRIS PLATA | C5: ='UNIFICADO x CODIGO'!B5 -> 0.65
A6: ='UNIFICADO x CODIGO'!A6 -> ADA0404 | B6: =VLOOKUP(A6,BASE!A:B,2,0) -> 3831 ADAPTADOR 175 BLANCO | C6: ='UNIFICADO x CODIGO'!B6 -> 0.16666667
A7: ='UNIFICADO x CODIGO'!A7 -> ADA0405 | B7: =VLOOKUP(A7,BASE!A:B,2,0) -> 744 ADAPTADOR 403 BLANCO | C7: ='UNIFICADO x CODIGO'!B7 -> 0.66666667
A8: ='UNIFICADO x CODIGO'!A8 -> ada0504 | B8: =VLOOKUP(A8,BASE!A:B,2,0) -> 744 ADAPTADOR 403 BRONCE | C8: ='UNIFICADO x CODIGO'!B8 -> 0.75
A9: ='UNIFICADO x CODIGO'!A9 -> ADA0601 | B9: =VLOOKUP(A9,BASE!A:B,2,0) -> 744 ADAPTADOR 403 NEGRO | C9: ='UNIFICADO x CODIGO'!B9 -> 0.16666667
A10: ='UNIFICADO x CODIGO'!A10 -> ADA0603 | B10: =VLOOKUP(A10,BASE!A:B,2,0) -> 8025 ADAPTADOR 158 NEGRO | C10: ='UNIFICADO x CODIGO'!B10 -> 4.3
A11: ='UNIFICADO x CODIGO'!A11 -> ADA0606 | B11: =VLOOKUP(A11,BASE!A:B,2,0) -> 3831 ADAPTADOR 175 NEGRO | C11: ='UNIFICADO x CODIGO'!B11 -> 1.5
A12: ='UNIFICADO x CODIGO'!A12 -> ADA0608 | B12: =VLOOKUP(A12,BASE!A:B,2,0) -> 7038 ADAPTADOR 840 NEGRO | C12: ='UNIFICADO x CODIGO'!B12 -> 0.43333333
A13: ='UNIFICADO x CODIGO'!A13 -> ALF0101 | B13: =VLOOKUP(A13,BASE!A:B,2,0) -> ALFAJIA S-332 MATE | C13: ='UNIFICADO x CODIGO'!B13 -> 0.51666667
... A174: ='UNIFICADO x CODIGO'!A174 -> RDU0101 | B174: =VLOOKUP(A174,BASE!A:B,2,0) -> RIEL DUCASSE 1764 MATE | C174: ='UNIFICADO x CODIGO'!B174 -> 1.7833333
A175: RDU0601 | B175: =VLOOKUP(A175,BASE!A:B,2,0) -> RIEL DUCASSE 1764 NEGRO | C175: 0.63
A176: ='UNIFICADO x CODIGO'!A176 -> ROS0301 | B176: =VLOOKUP(A176,BASE!A:B,2,0) -> RIEL OPTIGLASS SENCILLO SL-010 MATE | C176: ='UNIFICADO x CODIGO'!B176 -> 0.6
A177: ='UNIFICADO x CODIGO'!A177 -> ROS0302 | B177: =VLOOKUP(A177,BASE!A:B,2,0) -> RIEL OPTIGLASS DOBLE SL-011 MATE | C177: ='UNIFICADO x CODIGO'!B177 -> 1.3666667
A178: ROS0601 | B178: =VLOOKUP(A178,BASE!A:B,2,0) -> RIEL OPTIGLASS SENCILLO SL-010 NEGRO | C178: 0.32
A179: ='UNIFICADO x CODIGO'!A179 -> ROS0602 | B179: =VLOOKUP(A179,BASE!A:B,2,0) -> RIEL OPTIGLASS DOBLE SL-011 NEGRO | C179: ='UNIFICADO x CODIGO'!B179 -> 1.5833333
A180: ='UNIFICADO x CODIGO'!A180 -> SIL0101 | B180: =VLOOKUP(A180,BASE!A:B,2,0) -> SILLAR CABINA S-201 MATE | C180: ='UNIFICADO x CODIGO'!B180 -> 1.4833333
A181: ='UNIFICADO x CODIGO'!A181 -> SIL0102 | B181: =VLOOKUP(A181,BASE!A:B,2,0) -> 3831 SILLAR CABEZAL 173 MATE | C181: ='UNIFICADO x CODIGO'!B181 -> 1.3666667
A182: ='UNIFICADO x CODIGO'!A182 -> SIL0103 | B182: =VLOOKUP(A182,BASE!A:B,2,0) -> 3831 ADAPTADOR 175 MATE | C182: 1
A183: ='UNIFICADO x CODIGO'!A183 -> SIL0106 | B183: =VLOOKUP(A183,BASE!A:B,2,0) -> 8025 SILLAR 150 MATE | C183: ='UNIFICADO x CODIGO'!B183 -> 1.1166667
A184: ='UNIFICADO x CODIGO'!A184 -> SIL0109 | B184: =VLOOKUP(A184,BASE!A:B,2,0) -> 744 SILLAR 1856 TRES RIELES MATE | C184: ='UNIFICADO x CODIGO'!B184 -> 0.66666667
A185: ='UNIFICADO x CODIGO'!A185 -> SIL0110 | B185: =VLOOKUP(A185,BASE!A:B,2,0) -> 8025 SILLAR 707 MATE | C185: ='UNIFICADO x CODIGO'!B185 -> 1.1166667
A186: ='UNIFICADO x CODIGO'!A186 -> SIL0201 | B186: =VLOOKUP(A186,BASE!A:B,2,0) -> SILLAR CABINA S-201 GRIS PLATA | C186: ='UNIFICADO x CODIGO'!B186 -> 0.31666667
A187: ='UNIFICADO x CODIGO'!A187 -> SIL0205 | B187: =VLOOKUP(A187,BASE!A:B,2,0) -> 5020 SILLAR 194 GRIS PLATA | C187: ='UNIFICADO x CODIGO'!B187 -> 0.81666667
A188: ='UNIFICADO x CODIGO'!A188 -> SIL0207 | B188: =VLOOKUP(A188,BASE!A:B,2,0) -> 8025 SILLAR 150 GRIS PLATA | C188: ='UNIFICADO x CODIGO'!B188 -> 0.58333333
A189: ='UNIFICADO x CODIGO'!A189 -> SIL0212 | B189: =VLOOKUP(A189,BASE!A:B,2,0) -> 744 SILLAR 387 GRIS PLATA | C189: ='UNIFICADO x CODIGO'!B189 -> 0.2
A190: ='UNIFICADO x CODIGO'!A190 -> SIL0301 | B190: =VLOOKUP(A190,BASE!A:B,2,0) -> 3831 SILLAR CABEZAL 173 CRUDO | C190: ='UNIFICADO x CODIGO'!B190 -> 0.35
A191: ='UNIFICADO x CODIGO'!A191 -> SIL0305 | B191: =VLOOKUP(A191,BASE!A:B,2,0) -> 744 SILLAR 1856 TRES RIELES CRUDO | C191: ='UNIFICADO x CODIGO'!B191 -> 0.51666667
A192: ='UNIFICADO x CODIGO'!A192 -> SIL0402 | B192: =VLOOKUP(A192,BASE!A:B,2,0) -> 8025 SILLAR 707 BLANCO | C192: ='UNIFICADO x CODIGO'!B192 -> 0.58166667
A193: ='UNIFICADO x CODIGO'!A193 -> SIL0403 | B193: =VLOOKUP(A193,BASE!A:B,2,0) -> 8025 SILLAR 150 BLANCO | C193: ='UNIFICADO x CODIGO'!B193 -> 0.18333333
A194: ='UNIFICADO x CODIGO'!A194 -> SIL0404 | B194: =VLOOKUP(A194,BASE!A:B,2,0) -> 7038 SILLAR 701 BLANCO | C194: ='UNIFICADO x CODIGO'!B194 -> 0.48333333
... A300: ='UNIFICADO x CODIGO'!A300 -> ZSE0101 | B300: =VLOOKUP(A300,BASE!A:B,2,0) -> ZOCALO 10CMS S-351 MATE | C300: ='UNIFICADO x CODIGO'!B300 -> 0.16666667
A301: ='UNIFICADO x CODIGO'!A301 -> (en blanco) | C301: ='UNIFICADO x CODIGO'!B301 -> 0
A302: ='UNIFICADO x CODIGO'!A302 -> Total general | C302: ='UNIFICADO x CODIGO'!B302 -> 408.76817
A303: ='UNIFICADO x CODIGO'!A303 -> 0 | C303: ='UNIFICADO x CODIGO'!B303 -> 0
A304: ='UNIFICADO x CODIGO'!A304 -> 0 | C304: ='UNIFICADO x CODIGO'!B304 -> 0
A305: ='UNIFICADO x CODIGO'!A305 -> 0 | C305: ='UNIFICADO x CODIGO'!B305 -> 0
...

Sheet Inv Total mes
A1: INVENTARIO FEBRERO 28 DE 2026
A2: CONS. | B2: COD TEMPLEX | C2: DESCRIPCION | D2: COLOR | E2: REF. | F2: MM | G2: conversión
A3: 752 | B3: U570201 | C3: =VLOOKUP(B3,BASE!$A:$B,2,0) -> U57 GRIS PLATA | D3: =VLOOKUP(B3,BASE!$A:$D,3,0) -> GRIS PLATA | E3: =VLOOKUP(B3,BASE!$A:$E,4,0) -> U-57 | F3: 2000 | G3: =+F3/6000 -> 0.33333333
A4: 755 | B4: U570201 | C4: =VLOOKUP(B4,BASE!$A:$B,2,0) -> U57 GRIS PLATA | D4: =VLOOKUP(B4,BASE!$A:$D,3,0) -> GRIS PLATA | E4: =VLOOKUP(B4,BASE!$A:$E,4,0) -> U-57 | F4: 1880 | G4: =+F4/6000 -> 0.31333333
A5: 910 | B5: ZOC0105 | C5: =VLOOKUP(B5,BASE!$A:$B,2,0) -> ZOCALO 9CMS S-369 BRONCE MOVIL | D5: =VLOOKUP(B5,BASE!$A:$D,3,0) -> BRONCE | E5: =VLOOKUP(B5,BASE!$A:$E,4,0) -> S-369 | F5: 1300 | G5: =+F5/6000 -> 0.21666667
A6: 1093 | B6: CAB0207 | C6: =VLOOKUP(B6,BASE!$A:$B,2,0) -> 8025 CABEZAL 151 GRIS PLATA | D6: =VLOOKUP(B6,BASE!$A:$D,3,0) -> GRIS PLATA | E6: =VLOOKUP(B6,BASE!$A:$E,4,0) -> 151 | F6: 2600 | G6: =+F6/6000 -> 0.43333333
A7: 1316 | B7: CAB0401 | C7: =VLOOKUP(B7,BASE!$A:$B,2,0) -> CABEZAL CABINA S-319 BLANCO | D7: =VLOOKUP(B7,BASE!$A:$D,3,0) -> BLANCO | E7: =VLOOKUP(B7,BASE!$A:$E,4,0) -> S-319 | F7: 750 | G7: =+F7/6000 -> 0.125
A8: 1340 | B8: CAB0206 | C8: =VLOOKUP(B8,BASE!$A:$B,2,0) -> 8025 CABEZAL 706 BLANCO | D8: =VLOOKUP(B8,BASE!$A:$D,3,0) -> BLANCO | E8: =VLOOKUP(B8,BASE!$A:$E,4,0) -> 706 | F8: 3490 | G8: =+F8/6000 -> 0.58166667
A9: 1341 | B9: SIL0402 | C9: =VLOOKUP(B9,BASE!$A:$B,2,0) -> 8025 SILLAR 707 BLANCO | D9: =VLOOKUP(B9,BASE!$A:$D,3,0) -> BLANCO | E9: =VLOOKUP(B9,BASE!$A:$E,4,0) -> 707 | F9: 3490 | G9: =+F9/6000 -> 0.58166667
A10: 1546 | B10: ALF0105 | C10: =VLOOKUP(B10,BASE!$A:$B,2,0) -> SILLAR ALFAJIA 616 MATE | D10: =VLOOKUP(B10,BASE!$A:$D,3,0) -> MATE | E10: =VLOOKUP(B10,BASE!$A:$E,4,0) -> 616 | F10: 6000 | G10: =+F10/6000 -> 1
A11: 2054 | B11: U570201 | C11: =VLOOKUP(B11,BASE!$A:$B,2,0) -> U57 GRIS PLATA | D11: =VLOOKUP(B11,BASE!$A:$D,3,0) -> GRIS PLATA | E11: =VLOOKUP(B11,BASE!$A:$E,4,0) -> U-57 | F11: 2600 | G11: =+F11/6000 -> 0.43333333
A12: 2248 | B12: TUB0132 | C12: =VLOOKUP(B12,BASE!$A:$B,2,0) -> CUARTO CIRCULAR 1 1/2 " MATE | D12: =VLOOKUP(B12,BASE!$A:$D,3,0) -> MATE | E12: =VLOOKUP(B12,BASE!$A:$E,4,0) -> T-280 | F12: 2600 | G12: =+F12/6000 -> 0.43333333
A13: 2452 | B13: CAB0401 | C13: =VLOOKUP(B13,BASE!$A:$B,2,0) -> CABEZAL CABINA S-319 BLANCO | D13: =VLOOKUP(B13,BASE!$A:$D,3,0) -> BLANCO | E13: =VLOOKUP(B13,BASE!$A:$E,4,0) -> S-319 | F13: 950 | G13: =+F13/6000 -> 0.15833333
A14: 2585 | B14: CAB0203 | C14: =VLOOKUP(B14,BASE!$A:$B,2,0) -> 5020 CABEZAL 144 GRIS PLATA | D14: =VLOOKUP(B14,BASE!$A:$D,3,0) -> GRIS PLATA | E14: =VLOOKUP(B14,BASE!$A:$E,4,0) -> 144 | F14: 940 | G14: =+F14/6000 -> 0.15666667
... A58: 5743 | B58: ALF0503 | C58: =VLOOKUP(B58,BASE!$A:$B,2,0) -> ALFAJIA S-012 BRONCE | D58: =VLOOKUP(B58,BASE!$A:$D,3,0) -> BRONCE | E58: =VLOOKUP(B58,BASE!$A:$E,4,0) -> S-012 | F58: 1100 | G58: =+F58/6000 -> 0.18333333
A59: 5745 | B59: SIN CODIGO | C59: =VLOOKUP(B59,BASE!$A:$B,2,0) -> #N/A | D59: =VLOOKUP(B59,BASE!$A:$D,3,0) -> #N/A | E59: 1103 | F59: 3900 | G59: =+F59/6000 -> 0.65
A60: 5848 | B60: ADA0201 | C60: =VLOOKUP(B60,BASE!$A:$B,2,0) -> 8025 ADAPTADOR 158 GRIS PLATA | D60: =VLOOKUP(B60,BASE!$A:$D,3,0) -> GRIS PLATA | E60: =VLOOKUP(B60,BASE!$A:$E,4,0) -> 158 | F60: 4900 | G60: =+F60/6000 -> 0.81666667
A61: 5854 | B61: TUB0201 | C61: =VLOOKUP(B61,BASE!$A:$B,2,0) -> TUBULAR T-244 GRIS PLATA | D61: =VLOOKUP(B61,BASE!$A:$D,3,0) -> GRIS PLATA | E61: =VLOOKUP(B61,BASE!$A:$E,4,0) -> T-244 | F61: 2500 | G61: =+F61/6000 -> 0.41666667
A62: 5941 | B62: SILL0501 | C62: =VLOOKUP(B62,BASE!$A:$B,2,0) -> 5020 SILLAR ALFAJIA 581 BRONCE | D62: =VLOOKUP(B62,BASE!$A:$D,3,0) -> BRONCE | E62: =VLOOKUP(B62,BASE!$A:$E,4,0) -> 581 | F62: 1100 | G62: =+F62/6000 -> 0.18333333
A63: 6004 | B63: TRA0102 | C63: =VLOOKUP(B63,BASE!$A:$B,2,0) -> 5020 TRASLAPE 192 BRONCE | D63: =VLOOKUP(B63,BASE!$A:$D,3,0) -> BRONCE | E63: =VLOOKUP(B63,BASE!$A:$E,4,0) -> 192 | F63: 6000 | G63: =+F63/6000 -> 1
A64: 6115 | B64: SIL0207 | C64: =VLOOKUP(B64,BASE!$A:$B,2,0) -> 8025 SILLAR 150 GRIS PLATA | D64: =VLOOKUP(B64,BASE!$A:$D,3,0) -> GRIS PLATA | E64: =VLOOKUP(B64,BASE!$A:$E,4,0) -> 150 | F64: 1200 | G64: =+F64/6000 -> 0.2
A65: 6116 | B65: CAB0207 | C65: =VLOOKUP(B65,BASE!$A:$B,2,0) -> 8025 CABEZAL 151 GRIS PLATA | D65: =VLOOKUP(B65,BASE!$A:$D,3,0) -> GRIS PLATA | E65: =VLOOKUP(B65,BASE!$A:$E,4,0) -> 151 | F65: 1200 | G65: =+F65/6000 -> 0.2
A66: 6117 | B66: CAB0207 | C66: =VLOOKUP(B66,BASE!$A:$B,2,0) -> 8025 CABEZAL 151 GRIS PLATA | D66: =VLOOKUP(B66,BASE!$A:$D,3,0) -> GRIS PLATA | E66: =VLOOKUP(B66,BASE!$A:$E,4,0) -> 151 | F66: 1200 | G66: =+F66/6000 -> 0.2
A67: 6118 | B67: ENG0201 | C67: =VLOOKUP(B67,BASE!$A:$B,2,0) -> 8025 ENGANCHE 191 GRIS PLATA | D67: =VLOOKUP(B67,BASE!$A:$D,3,0) -> GRIS PLATA | E67: =VLOOKUP(B67,BASE!$A:$E,4,0) -> 191 | F67: 1300 | G67: =+F67/6000 -> 0.21666667
A68: 6119 | B68: ENG0201 | C68: =VLOOKUP(B68,BASE!$A:$B,2,0) -> 8025 ENGANCHE 191 GRIS PLATA | D68: =VLOOKUP(B68,BASE!$A:$D,3,0) -> GRIS PLATA | E68: =VLOOKUP(B68,BASE!$A:$E,4,0) -> 191 | F68: 1300 | G68: =+F68/6000 -> 0.21666667
A69: 6120 | B69: ENG0201 | C69: =VLOOKUP(B69,BASE!$A:$B,2,0) -> 8025 ENGANCHE 191 GRIS PLATA | D69: =VLOOKUP(B69,BASE!$A:$D,3,0) -> GRIS PLATA | E69: =VLOOKUP(B69,BASE!$A:$E,4,0) -> 191 | F69: 1300 | G69: =+F69/6000 -> 0.21666667
A70: 6121 | B70: ENG0201 | C70: =VLOOKUP(B70,BASE!$A:$B,2,0) -> 8025 ENGANCHE 191 GRIS PLATA | D70: =VLOOKUP(B70,BASE!$A:$D,3,0) -> GRIS PLATA | E70: =VLOOKUP(B70,BASE!$A:$E,4,0) -> 191 | F70: 1300 | G70: =+F70/6000 -> 0.21666667
A71: 6143 | B71: ADA0206 | C71: =VLOOKUP(B71,BASE!$A:$B,2,0) -> 744 ADAPTADOR 403 GRIS PLATA | D71: =VLOOKUP(B71,BASE!$A:$D,3,0) -> GRIS PLATA | E71: =VLOOKUP(B71,BASE!$A:$E,4,0) -> 403 | F71: 3900 | G71: =+F71/6000 -> 0.65
... A244: 9028 | B244: JAM0306 | C244: =VLOOKUP(B244,BASE!$A:$B,2,0) -> 744 JAMBA 393 CRUDO | D244: =VLOOKUP(B244,BASE!$A:$D,3,0) -> CRUDO | E244: =VLOOKUP(B244,BASE!$A:$E,4,0) -> 393 | F244: 1700 | G244: =+F244/6000 -> 0.28333333
A245: 9029 | B245: SIL0301 | C245: =VLOOKUP(B245,BASE!$A:$B,2,0) -> 3831 SILLAR CABEZAL 173 CRUDO | D245: =VLOOKUP(B245,BASE!$A:$D,3,0) -> CRUDO | E245: 173 | F245: 2100 | G245: =+F245/6000 -> 0.35
A246: 9030 | B246: PER0303 | C246: =VLOOKUP(B246,BASE!$A:$B,2,0) -> PERSIANA 315 CRUDO | D246: =VLOOKUP(B246,BASE!$A:$D,3,0) -> CRUDO | E246: =VLOOKUP(B246,BASE!$A:$E,4,0) -> 315 | F246: 1300 | G246: =+F246/6000 -> 0.21666667
A247: 9032 | B247: TUB0304 | C247: =VLOOKUP(B247,BASE!$A:$B,2,0) -> TUBULAR T-94 CRUDO | D247: =VLOOKUP(B247,BASE!$A:$D,3,0) -> CRUDO | E247: =VLOOKUP(B247,BASE!$A:$E,4,0) -> T-94 | F247: 1000 | G247: =+F247/6000 -> 0.16666667
A248: 9041 | B248: PER0303 | C248: =VLOOKUP(B248,BASE!$A:$B,2,0) -> PERSIANA 315 CRUDO | D248: =VLOOKUP(B248,BASE!$A:$D,3,0) -> CRUDO | E248: =VLOOKUP(B248,BASE!$A:$E,4,0) -> 315 | F248: 6000 | G248: =+F248/6000 -> 1
A249: 9051 | B249: F080601 | C249: =VLOOKUP(B249,BASE!$A:$B,2,0) -> TABLILLA F-08 NEGRA | D249: =VLOOKUP(B249,BASE!$A:$D,3,0) -> NEGRO | E249: =VLOOKUP(B249,BASE!$A:$E,4,0) -> F-08 | F249: 3300 | G249: =+F249/6000 -> 0.55
A250: 9052 | B250: SIL0109 | C250: =VLOOKUP(B250,BASE!$A:$B,2,0) -> 744 SILLAR 1856 TRES RIELES MATE | D250: =VLOOKUP(B250,BASE!$A:$D,3,0) -> MATE | E250: =VLOOKUP(B250,BASE!$A:$E,4,0) -> 1856 | F250: 4000 | G250: =+F250/6000 -> 0.66666667
A251: 9053 | B251: CAB0109 | C251: =VLOOKUP(B251,BASE!$A:$B,2,0) -> 744 CABEZAL 1857 TRES RIELES MATE | D251: =VLOOKUP(B251,BASE!$A:$D,3,0) -> MATE | E251: =VLOOKUP(B251,BASE!$A:$E,4,0) -> 1857 | F251: 4000 | G251: =+F251/6000 -> 0.66666667
A252: 9055 | B252: TUB0607 | C252: =VLOOKUP(B252,BASE!$A:$B,2,0) -> TUBULAR 1102 NEGRO | D252: =VLOOKUP(B252,BASE!$A:$D,3,0) -> NEGRO | E252: =VLOOKUP(B252,BASE!$A:$E,4,0) -> 1102 | F252: 700 | G252: =+F252/6000 -> 0.11666667
A253: 9056 | B253: TUB0607 | C253: =VLOOKUP(B253,BASE!$A:$B,2,0) -> TUBULAR 1102 NEGRO | D253: =VLOOKUP(B253,BASE!$A:$D,3,0) -> NEGRO | E253: =VLOOKUP(B253,BASE!$A:$E,4,0) -> 1102 | F253: 700 | G253: =+F253/6000 -> 0.11666667
A254: 9057 | B254: PEF0106 | C254: =VLOOKUP(B254,BASE!$A:$B,2,0) -> PERFIL F 463 NEGRO | D254: =VLOOKUP(B254,BASE!$A:$D,3,0) -> NEGRO | E254: =VLOOKUP(B254,BASE!$A:$E,4,0) -> F-463 | F254: 700 | G254: =+F254/6000 -> 0.11666667
A255: 9075 | B255: ANG0409 | C255: =VLOOKUP(B255,BASE!$A:$B,2,0) -> ANGULO A-01 BLANCO (1/2 X 1/2) | D255: =VLOOKUP(B255,BASE!$A:$D,3,0) -> BLANCO | E255: =VLOOKUP(B255,BASE!$A:$E,4,0) -> A-01 | F255: 2100 | G255: =+F255/6000 -> 0.35
...

Sheet INV COMPARADO
A1: Código | B1: Descripción | C1: Exi. WO | D1: Exi. Fisica | E1: Diferencia
A2: ADA0102 | B2: =VLOOKUP(A2,BASE!$A:$B,2,0) -> 8025 ADAPTADOR 158 MATE | C2: 0.263333 | D2: =IFERROR(VLOOKUP(A2,'TD mes'!A:C,3,0),0) -> 0.26666667 | E2: =+D2-C2 -> 0.0033336667
A3: ADA0103 | B3: =VLOOKUP(A3,BASE!$A:$B,2,0) -> 744 ADAPTADOR 403 MATE | C3: 1.05 | D3: =IFERROR(VLOOKUP(A3,'TD mes'!A:C,3,0),0) -> 1 | E3: =+D3-C3 -> -0.05
A4: ADA0201 | B4: =VLOOKUP(A4,BASE!$A:$B,2,0) -> 8025 ADAPTADOR 158 GRIS PLATA | C4: 0.82 | D4: =IFERROR(VLOOKUP(A4,'TD mes'!A:C,3,0),0) -> 0.81666667 | E4: =+D4-C4 -> -0.0033333333
A5: ADA0204 | B5: =VLOOKUP(A5,BASE!$A:$B,2,0) -> 3831 ADAPTADOR 175 GRIS PLATA | C5: 0.003333 | D5: =IFERROR(VLOOKUP(A5,'TD mes'!A:C,3,0),0) -> 0 | E5: =+D5-C5 -> -0.003333
A6: ADA0206 | B6: =VLOOKUP(A6,BASE!$A:$B,2,0) -> 744 ADAPTADOR 403 GRIS PLATA | C6: 0.65 | D6: =IFERROR(VLOOKUP(A6,'TD mes'!A:C,3,0),0) -> 0.65 | E6: =+D6-C6 -> 0
A7: ADA0404 | B7: =VLOOKUP(A7,BASE!$A:$B,2,0) -> 3831 ADAPTADOR 175 BLANCO | C7: 0.17 | D7: =IFERROR(VLOOKUP(A7,'TD mes'!A:C,3,0),0) -> 0.16666667 | E7: =+D7-C7 -> -0.0033333333
A8: ADA0405 | B8: =VLOOKUP(A8,BASE!$A:$B,2,0) -> 744 ADAPTADOR 403 BLANCO | C8: 0.67 | D8: =IFERROR(VLOOKUP(A8,'TD mes'!A:C,3,0),0) -> 0.66666667 | E8: =+D8-C8 -> -0.0033333333
A9: ADA0504 | B9: =VLOOKUP(A9,BASE!$A:$B,2,0) -> 744 ADAPTADOR 403 BRONCE | C9: 0.75 | D9: =IFERROR(VLOOKUP(A9,'TD mes'!A:C,3,0),0) -> 0.75 | E9: =+D9-C9 -> 0
A10: ADA0601 | B10: =VLOOKUP(A10,BASE!$A:$B,2,0) -> 744 ADAPTADOR 403 NEGRO | C10: 0.163333 | D10: =IFERROR(VLOOKUP(A10,'TD mes'!A:C,3,0),0) -> 0.16666667 | E10: =+D10-C10 -> 0.0033336667
A11: ADA0603 | B11: =VLOOKUP(A11,BASE!$A:$B,2,0) -> 8025 ADAPTADOR 158 NEGRO | C11: 4.298333 | D11: =IFERROR(VLOOKUP(A11,'TD mes'!A:C,3,0),0) -> 4.3 | E11: =+D11-C11 -> 0.001667
A12: ADA0606 | B12: =VLOOKUP(A12,BASE!$A:$B,2,0) -> 3831 ADAPTADOR 175 NEGRO | C12: 3.25 | D12: =IFERROR(VLOOKUP(A12,'TD mes'!A:C,3,0),0) -> 1.5 | E12: =+D12-C12 -> -1.75
A13: ADA0608 | B13: =VLOOKUP(A13,BASE!$A:$B,2,0) -> 7038 ADAPTADOR 840 NEGRO | C13: 0.43 | D13: =IFERROR(VLOOKUP(A13,'TD mes'!A:C,3,0),0) -> 0.43333333 | E13: =+D13-C13 -> 0.0033333333
... A293: ZSE0206 | B293: =VLOOKUP(A293,BASE!$A:$B,2,0) -> ZOCALO 10CMS S-351 NEGRO | C293: 0.344833 | D293: =IFERROR(VLOOKUP(A293,'TD mes'!A:C,3,0),0) -> 0.36666667 | E293: =+D293-C293 -> 0.021833667

Sheet CONSECUTIVO
A1: CONS. | B1: COD TEMPLEX | C1: DESCRIPCION | D1: COLOR | E1: REF. | F1: MM | G1: UBICACIÓN
A2: 10251
A3: =A2+1 -> 10252
A4: =A3+1 -> 10253
A5: =A4+1 -> 10254
A6: =A5+1 -> 10255
A7: =A6+1 -> 10256
A8: =A7+1 -> 10257
A9: =A8+1 -> 10258
A10: =A9+1 -> 10259
A11: =A10+1 -> 10260
A12: =A11+1 -> 10261
A13: =A12+1 -> 10262
A14: =A13+1 -> 10263
... A35: =A34+1 -> 10284
